<?xml version='1.0'?>


<robot name="mybot1" xmlns:xacro="http://www.ros.org/wiki/xacro">
<xacro:include filename="$(find final_robot)/urdf/mybot.gazebo" />

<!-- +++++++++++++++++++++++Robot Definition+++++++++++++++++++++++++ /-->

<!--Chassis & Caster Link /-->

 <link name='chassis'>

   <visual name='chassis_visual'>

      <origin xyz="0 0 0" rpy=" 0 0 0"/>

      <geometry>
        <box size=".6 .3 .1"/>
      </geometry>

    </visual>    
     
   <inertial>

      <mass value="10.0"/>
      <origin xyz="0 0 0" rpy=" 0 0 0"/>
      <inertia
          ixx="0.5" ixy="0" ixz="0"
          iyy="1.0" iyz="0"
          izz="0.1"
      />

   </inertial>

   <collision name='collision'>
      <geometry>
        <box size=".6 .3 .1"/>
      </geometry>
   </collision>



 <collision name='caster_collision'>
    <origin xyz="-0.2 0 -0.05" rpy=" 0 0 0"/>

    <geometry>
        <sphere radius="0.05"/>
    </geometry>

    <surface>

        <friction>
          <ode>
            <mu>0</mu>
            <mu2>0</mu2>
            <slip1>1.0</slip1>
            <slip2>1.0</slip2>
          </ode>
        </friction>

     </surface>

 </collision>

<visual name='caster_visual'>

     <origin xyz="-0.2 0 -0.05" rpy=" 0 0 0"/>

     <geometry>
      <sphere radius="0.05"/>
     </geometry>

</visual>

</link>

<!-- ++++++++++++++++ weight_balance +++++++++++++++++++++++++++++++ /-->

<link name="weight_balance">
        <inertial>
            <origin xyz="0.0 0.0 0.0" />
              <mass value="5.0"/>
            <inertia ixx="0.1" ixy="0.0" ixz="0.0" iyy="0.1" iyz="0.0" izz="0.1" />
        </inertial>
        <visual>
            <origin xyz="-0.15 0.0 0.07" />
            <geometry>
                <box size="0.08 0.2 0.02" />
            </geometry>
        </visual>
        <collision>
            <origin xyz="-0.0 0.0 0.2" rpy="0.0 0.0 0.0" />
            <geometry>
                <box size="0.05 0.05 0.05" />
            </geometry>
        </collision>
</link>

<joint name="balance_joint" type="fixed">

    <origin xyz="0 0 0" rpy="0 0 0"/>

    <parent link="chassis"/>
    <child link="weight_balance"/>

</joint>

<!-- ++++++++++++++++Left wheel+++++++++++++++++++++++++++++++ /-->





<!--left wheel Link /-->

 <link name="left_wheel">

    <visual name="left_wheel_visual">
      <origin xyz="0 0 0" rpy="0 1.5707 1.5707"/>
      <geometry>
        <cylinder radius="0.1" length="0.05"/>
      </geometry>
    </visual>


    <collision name="collision">
      <origin xyz="0 0 0" rpy="0 1.5707 1.5707"/>
      <geometry>
        <cylinder radius="0.1" length="0.05"/>
      </geometry>
    </collision>

    

    <inertial>
      <origin xyz="0 0 0" rpy="0 1.5707 1.5707"/>
      <mass value="5"/>
      <cylinder_inertia m="5" r="0.1" h="0.05"/>
      <inertia
        ixx="1.0" ixy="0.0" ixz="0.0"
        iyy="1.0" iyz="0.0"
        izz="1.0"/>
    </inertial>

 </link>

<!--left wheel Joint /-->

  <joint type="continuous" name="left_wheel_hinge">
    <origin xyz="0.1 0.175 0" rpy="0 0 0"/>
    <child link="left_wheel"/>
    <parent link="chassis"/>
    <axis xyz="0 1 0" rpy="0 0 0"/>
    <limit effort="100" velocity="100"/>
    <joint_properties damping="0.0" friction="0.0"/>
  </joint>

<!-- +++++++++++++++++++ Right Wheel +++++++++++++++++++++++++++++++++ /-->

<!--Right Wheel link /-->

  <link name="right_wheel">

    <visual name="right_wheel_visual">

      <origin xyz="0 0 0" rpy="0 1.5707 1.5707"/>

      <geometry>
        <cylinder radius="0.1" length="0.05"/>
      </geometry>

    </visual>

    
    <collision name="collision">

      <origin xyz="0 0 0" rpy="0 1.5707 1.5707"/>

      <geometry>
        <cylinder radius="0.1" length="0.05"/>
      </geometry>

    </collision>


    <inertial>

      <origin xyz="0 0 0" rpy="0 1.5707 1.5707"/>
      <mass value="5"/>
      <cylinder_inertia m="5" r="0.1" h="0.05"/>

      <inertia
        ixx="1.0" ixy="0.0" ixz="0.0"
        iyy="1.0" iyz="0.0"
        izz="1.0"/>
      </inertial>

  </link>

<!--Right wheel joint/-->
  <joint type="continuous" name="right_wheel_hinge">

    <origin xyz="0.1 -0.175 0" rpy="0 0 0"/>
    
    <child link="right_wheel"/>
    <parent link="chassis"/>

    <axis xyz="0 1 0" rpy="0 0 0"/>

    <limit effort="100" velocity="100"/>

    <joint_properties damping="0.0" friction="0.0"/>

  </joint>

<!-- ++++++++++++++++++  Kinect  +++++++++++++++++++++++++++++ /-->
<!--Kinect  Link /-->

<link name="camera_link">
    
 <visual>
      <origin xyz=".18 0 -0.1" rpy="0 0 0"/>
      <geometry>
      <mesh filename="package://final_robot/meshes/kinect.dae"/>
      </geometry>
 </visual>
    
 <collision>
    <origin xyz="0 0 0" rpy="0 0 0"/>

    <geometry>
    <box size="0.1 0.1 0.1"/>
    </geometry>
    
 </collision>

 <inertial>
     <mass value="1e-5" />
     <origin xyz=".18 0 -0.1" rpy="0 0 0"/>
     <inertia ixx="1e-6" ixy="0" ixz="0" iyy="1e-6" iyz="0" izz="1e-6" />
 </inertial>

</link>

<!--kinect joint /-->

<joint name="kinect_joint" type="fixed">

    <origin xyz=".15 0 .05" rpy="0 0 0"/>

    <parent link="chassis"/>
    <child link="camera_link"/>

</joint>



<!--  Kinect Optical Link and joints   /-->

<joint name="kinect_optical_joint" type="fixed">

<origin xyz="0 0 0" rpy="-1.5707 0 -1.5707"/> <!-- To invert the coordinates from image convention (Z is forward) to normal xyz /-->
<parent link="camera_link"/>
<child link="kinect_optical"/>
</joint>

<!--Virtual link to project the images to, and then flip it to us as its joint is flipped  /-->
<link name="kinect_optical">
</link>


    <!-- LIDAR LINK -->
    <link name="lider">
        <inertial>
            <origin xyz="0.0 0.0 0.0" rpy="0.0 0.0 0.0" />
            <mass value="0.9" />
            <inertia ixx="1.0" ixy="0.0" ixz="0.0" iyy="1.0" iyz="0.0" izz="1.0" />
        </inertial>
        <visual>
            <origin xyz=" 0 0 0" rpy="0 0 0" />
            <geometry>
                <mesh filename="package://final_robot/meshes/hokuyo.dae" />
            </geometry>
        </visual>

        <collision>
            <origin xyz="0.0 0.0 0.0" rpy="0.0 0.0 0.0" />
            <geometry>
                <mesh filename="package://final_robot/meshes/hokuyo.dae" />
            </geometry>
        </collision>
    </link>
    <joint name="lider_joint" type="fixed">
        <origin xyz="0.25 0.0 0.13" rpy="0 0 0" />
        <parent link="lider_tower" />
        <child link="lider" />
        <axis xyz="0 0 0" />
    </joint>

    <!-- LIDAR TOWER LINK -->

    <link name="lider_tower">
        <inertial>
            <origin xyz="0.0 0.0 0.0" />
              <mass value="0.2"/>
            <inertia ixx="0.1" ixy="0.0" ixz="0.0" iyy="0.1" iyz="0.0" izz="0.1" />
        </inertial>
        <visual>
            <origin xyz="0.25 0.0 0.07" />
            <geometry>
                <box size="0.08 0.08 0.06" />
            </geometry>
        </visual>
        <collision>
            <origin xyz="-0.0 0.0 0.0" rpy="0.0 0.0 0.0" />
            <geometry>
                <box size="0.1 0.1 0.1" />
            </geometry>
        </collision>
</link>

<joint name="lider_tower_joint" type="fixed">

    <origin xyz="0 0 0" rpy="0 0 0"/>

    <parent link="chassis"/>
    <child link="lider_tower"/>

</joint>
    
</robot>
